ERROR:guardar:Exception on / [GET]
Traceback (most recent call last):
  File "C:\Users\administrador.PARQUE-EXPLORA\AppData\Local\Programs\Python\Python312\Lib\site-packages\flask\app.py", line 1455, in wsgi_app
    response = self.full_dispatch_request()
               ^^^^^^^^^^^^^^^^^^^^^^^^^^^^
  File "C:\Users\administrador.PARQUE-EXPLORA\AppData\Local\Programs\Python\Python312\Lib\site-packages\flask\app.py", line 869, in full_dispatch_request
    rv = self.handle_user_exception(e)
         ^^^^^^^^^^^^^^^^^^^^^^^^^^^^^
  File "C:\Users\administrador.PARQUE-EXPLORA\AppData\Local\Programs\Python\Python312\Lib\site-packages\flask\app.py", line 867, in full_dispatch_request
    rv = self.dispatch_request()
         ^^^^^^^^^^^^^^^^^^^^^^^
  File "C:\Users\administrador.PARQUE-EXPLORA\AppData\Local\Programs\Python\Python312\Lib\site-packages\flask\app.py", line 852, in dispatch_request
    return self.ensure_sync(self.view_functions[rule.endpoint])(**view_args)
           ^^^^^^^^^^^^^^^^^^^^^^^^^^^^^^^^^^^^^^^^^^^^^^^^^^^^^^^^^^^^^^^^^
  File "C:\cheklistexperiencia\src\guardar.py", line 28, in home1
    with db.database.cursor() as cursor:
         ^^^^^^^^^^^^^^^^^^^^
  File "C:\Users\administrador.PARQUE-EXPLORA\AppData\Local\Programs\Python\Python312\Lib\site-packages\mysql\connector\connection_cext.py", line 728, in cursor
    raise OperationalError("MySQL Connection not available.")
mysql.connector.errors.OperationalError: MySQL Connection not available.
ERROR:guardar:Exception on / [GET]
Traceback (most recent call last):
  File "C:\Users\administrador.PARQUE-EXPLORA\AppData\Local\Programs\Python\Python312\Lib\site-packages\flask\app.py", line 1455, in wsgi_app
    response = self.full_dispatch_request()
               ^^^^^^^^^^^^^^^^^^^^^^^^^^^^
  File "C:\Users\administrador.PARQUE-EXPLORA\AppData\Local\Programs\Python\Python312\Lib\site-packages\flask\app.py", line 869, in full_dispatch_request
    rv = self.handle_user_exception(e)
         ^^^^^^^^^^^^^^^^^^^^^^^^^^^^^
  File "C:\Users\administrador.PARQUE-EXPLORA\AppData\Local\Programs\Python\Python312\Lib\site-packages\flask\app.py", line 867, in full_dispatch_request
    rv = self.dispatch_request()
         ^^^^^^^^^^^^^^^^^^^^^^^
  File "C:\Users\administrador.PARQUE-EXPLORA\AppData\Local\Programs\Python\Python312\Lib\site-packages\flask\app.py", line 852, in dispatch_request
    return self.ensure_sync(self.view_functions[rule.endpoint])(**view_args)
           ^^^^^^^^^^^^^^^^^^^^^^^^^^^^^^^^^^^^^^^^^^^^^^^^^^^^^^^^^^^^^^^^^
  File "C:\cheklistexperiencia\src\guardar.py", line 28, in home1
    with db.database.cursor() as cursor:
         ^^^^^^^^^^^^^^^^^^^^
  File "C:\Users\administrador.PARQUE-EXPLORA\AppData\Local\Programs\Python\Python312\Lib\site-packages\mysql\connector\connection_cext.py", line 728, in cursor
    raise OperationalError("MySQL Connection not available.")
mysql.connector.errors.OperationalError: MySQL Connection not available.
ERROR:guardar:Exception on / [GET]
Traceback (most recent call last):
  File "C:\Users\administrador.PARQUE-EXPLORA\AppData\Local\Programs\Python\Python312\Lib\site-packages\flask\app.py", line 1455, in wsgi_app
    response = self.full_dispatch_request()
               ^^^^^^^^^^^^^^^^^^^^^^^^^^^^
  File "C:\Users\administrador.PARQUE-EXPLORA\AppData\Local\Programs\Python\Python312\Lib\site-packages\flask\app.py", line 869, in full_dispatch_request
    rv = self.handle_user_exception(e)
         ^^^^^^^^^^^^^^^^^^^^^^^^^^^^^
  File "C:\Users\administrador.PARQUE-EXPLORA\AppData\Local\Programs\Python\Python312\Lib\site-packages\flask\app.py", line 867, in full_dispatch_request
    rv = self.dispatch_request()
         ^^^^^^^^^^^^^^^^^^^^^^^
  File "C:\Users\administrador.PARQUE-EXPLORA\AppData\Local\Programs\Python\Python312\Lib\site-packages\flask\app.py", line 852, in dispatch_request
    return self.ensure_sync(self.view_functions[rule.endpoint])(**view_args)
           ^^^^^^^^^^^^^^^^^^^^^^^^^^^^^^^^^^^^^^^^^^^^^^^^^^^^^^^^^^^^^^^^^
  File "C:\cheklistexperiencia\src\guardar.py", line 28, in home1
    with db.database.cursor() as cursor:
         ^^^^^^^^^^^^^^^^^^^^
  File "C:\Users\administrador.PARQUE-EXPLORA\AppData\Local\Programs\Python\Python312\Lib\site-packages\mysql\connector\connection_cext.py", line 728, in cursor
    raise OperationalError("MySQL Connection not available.")
mysql.connector.errors.OperationalError: MySQL Connection not available.